<?xml version='1.0' encoding='utf-8'?>
<mujoco model="table_arena">
  <asset>
    <texture builtin="gradient" height="256" rgb1=".9 .9 1." rgb2=".2 .3 .4" type="skybox" width="256" />
    <material name="floorplane_mat" specular="0" shininess="0" reflectance="0.1" rgba="0.8 0.8 0.8 1" />
    <material name="wall_mat" specular="0" shininess="0" reflectance="0" rgba="0.95 0.95 0.95 1" />
    <material name="table_top_mat" specular="0.1" shininess="0.1" reflectance="0.2" rgba="0.7 0.7 0.7 1" />
    <material name="table_leg_mat" specular="0.8" shininess="0.8" reflectance="0.5" rgba="0.4 0.4 0.4 1" />
    <texture file="../libero_assets/stable_scanned_objects/white_bowl/texture.png" name="object_1_tex-model" type="2d" />
    <material name="object_1_model" reflectance="0.5" texrepeat="1 1" texture="object_1_tex-model" texuniform="false" />
    <mesh file="../libero_assets/stable_scanned_objects/white_bowl/visual/model_vis.msh" name="object_1_model_vis" scale="0.5 0.5 0.5" />
    <texture file="../libero_assets/stable_scanned_objects/white_bowl/texture.png" name="object_2_tex-model" type="2d" />
    <material name="object_2_model" reflectance="0.5" texrepeat="1 1" texture="object_2_tex-model" texuniform="false" />
    <mesh file="../libero_assets/stable_scanned_objects/white_bowl/visual/model_vis.msh" name="object_2_model_vis" scale="0.5 0.5 0.5" />
    <texture file="../libero_assets/stable_hope_objects/ketchup/texture_map.png" name="object_3_tex-textured" type="2d" />
    <material name="object_3_textured" reflectance="0.5" texrepeat="1 1" texture="object_3_tex-textured" texuniform="false" />
    <mesh file="../libero_assets/stable_hope_objects/ketchup/visual/textured_vis.msh" name="object_3_textured_vis" scale="0.01 0.01 0.01" />
    <texture file="../libero_assets/stable_hope_objects/ketchup/texture_map.png" name="object_4_tex-textured" type="2d" />
    <material name="object_4_textured" reflectance="0.5" texrepeat="1 1" texture="object_4_tex-textured" texuniform="false" />
    <mesh file="../libero_assets/stable_hope_objects/ketchup/visual/textured_vis.msh" name="object_4_textured_vis" scale="0.01 0.01 0.01" />
    <material name="tidybot_black" rgba="0.11372549 0.11372549 0.10196078 1" />
    <material name="tidybot_gray" rgba="0.62745098 0.65098039 0.64705882 1" />
    <material name="tidybot_dark_gray" rgba="0.35294118 0.37647059 0.37254902 1" />
    <mesh file="../assets/base/bumper.stl" name="tidybot_bumper" />
    <mesh file="../assets/base/bottom_plate.stl" name="tidybot_bottom_plate" />
    <mesh file="../assets/base/body.stl" name="tidybot_body" />
    <mesh file="../assets/base/top_plate.stl" name="tidybot_top_plate" />
    <mesh file="../assets/base/arm_plate.stl" name="tidybot_arm_plate" />
    <mesh name="tidybot_gen3/base_link" file="../assets/gen3/base_link.stl" />
    <mesh name="tidybot_shoulder_link" file="../assets/gen3/shoulder_link.stl" />
    <mesh name="tidybot_half_arm_1_link" file="../assets/gen3/half_arm_1_link.stl" />
    <mesh name="tidybot_half_arm_2_link" file="../assets/gen3/half_arm_2_link.stl" />
    <mesh name="tidybot_forearm_link" file="../assets/gen3/forearm_link.stl" />
    <mesh name="tidybot_spherical_wrist_1_link" file="../assets/gen3/spherical_wrist_1_link.stl" />
    <mesh name="tidybot_spherical_wrist_2_link" file="../assets/gen3/spherical_wrist_2_link.stl" />
    <mesh name="tidybot_bracelet_with_vision_link" file="../assets/gen3/bracelet_with_vision_link.stl" />
    <material name="tidybot_metal" rgba="0.58 0.58 0.58 1" />
    <material name="tidybot_silicone" rgba="0.1882 0.1882 0.1882 1" />
    <material name="tidybot_2f85/gray" rgba="0.4627 0.4627 0.4627 1" />
    <material name="tidybot_2f85/black" rgba="0.149 0.149 0.149 1" />
    <mesh class="2f85" file="../assets/2f85/base.stl" name="tidybot_base" />
    <mesh class="2f85" file="../assets/2f85/driver.stl" name="tidybot_driver" />
    <mesh class="2f85" file="../assets/2f85/coupler.stl" name="tidybot_coupler" />
    <mesh class="2f85" file="../assets/2f85/follower.stl" name="tidybot_follower" />
    <mesh class="2f85" file="../assets/2f85/pad.stl" name="tidybot_pad" />
    <mesh class="2f85" file="../assets/2f85/silicone_pad.stl" name="tidybot_silicone_pad" />
    <mesh class="2f85" file="../assets/2f85/spring_link.stl" name="tidybot_spring_link" />
  </asset>
  <worldbody>
    <geom condim="3" group="1" material="floorplane_mat" name="floor" pos="0 0 0" size="3 3 .125" type="plane" />
    <geom pos="-1.25 2.25 1.5" quat="0.6532815 0.6532815 0.2705981 0.2705981" size="1.06 1.5 0.01" type="box" conaffinity="0" contype="0" group="1" name="wall_leftcorner_visual" material="wall_mat" />
    <geom pos="-1.25 -2.25 1.5" quat="0.6532815 0.6532815 -0.2705981 -0.2705981" size="1.06 1.5 0.01" type="box" conaffinity="0" contype="0" group="1" name="wall_rightcorner_visual" material="wall_mat" />
    <geom pos="1.25 3 1.5" quat="0.7071 0.7071 0 0" size="1.75 1.5 0.01" type="box" conaffinity="0" contype="0" group="1" name="wall_left_visual" material="wall_mat" />
    <geom pos="1.25 -3 1.5" quat="0.7071 -0.7071 0 0" size="1.75 1.5 0.01" type="box" conaffinity="0" contype="0" group="1" name="wall_right_visual" material="wall_mat" />
    <geom pos="-2 0 1.5" quat="0.5 0.5 0.5 0.5" size="1.5 1.5 0.01" type="box" conaffinity="0" contype="0" group="1" name="wall_rear_visual" material="wall_mat" />
    <geom pos="3 0 1.5" quat="0.5 0.5 -0.5 -0.5" size="3 1.5 0.01" type="box" conaffinity="0" contype="0" group="1" name="wall_front_visual" material="wall_mat" />
    <body name="table" pos="0 0 0.4">
      <geom pos="0 0 0" size="0.5 0.6 0.025" type="box" group="0" name="table_collision" friction="1 0.005 0.0001" />
      <geom name="table_visual" size="0.5 0.6 0.025" type="box" contype="0" conaffinity="0" group="1" material="table_top_mat" />
      <geom name="table_leg1_visual" size="0.025 0.4375" pos="0.4 0.5 -0.4375" type="cylinder" contype="0" conaffinity="0" group="1" material="table_leg_mat" />
      <geom name="table_leg2_visual" size="0.025 0.4375" pos="-0.4 0.5 -0.4375" type="cylinder" contype="0" conaffinity="0" group="1" material="table_leg_mat" />
      <geom name="table_leg3_visual" size="0.025 0.4375" pos="-0.4 -0.5 -0.4375" type="cylinder" contype="0" conaffinity="0" group="1" material="table_leg_mat" />
      <geom name="table_leg4_visual" size="0.025 0.4375" pos="0.4 -0.5 -0.4375" type="cylinder" contype="0" conaffinity="0" group="1" material="table_leg_mat" />
    </body>
    <light pos="1.0 1.0 1.5" dir="-0.2 -0.2 -1" specular="0.3 0.3 0.3" directional="true" castshadow="false" />
    <camera mode="fixed" name="frontview" pos="1.6 0 1.45" quat="0.56 0.43 0.43 0.56" />
    <camera mode="fixed" name="birdview" pos="-0.2 0 3.0" quat="0.7071 0 0 0.7071" />
    <camera mode="fixed" name="agentview" pos="0.5 0 1.35" quat="0.653 0.271 0.271 0.653" />
    <camera mode="fixed" name="sideview" pos="-0.05651774593317116 1.2761224129427358 1.4879572214102434" quat="0.009905065491771751 0.006877963156909582 0.5912228352893879 0.806418094001364" />
    <body name="object_1_instance" pos="-0.5008460274930173 -0.025743497362280918 0.44500000000000006">
      <freejoint />
      <geom solimp="0.998 0.998 0.001" solref="0.001 1" density="100" friction="0.95 0.3 0.1" type="mesh" mesh="object_1_model_vis" conaffinity="0" contype="0" group="1" material="object_1_model" />
      <geom solimp="0.998 0.998 0.001" solref="0.001 1" density="100" friction="0.95 0.3 0.1" type="box" pos="0.00000 0.00009 0.00240" quat="0.70711 0.00000 0.70711 0.00000" size="0.00184 0.01653 0.01728" group="0" rgba="0.8 0.8 0.8 0.3" />
      <geom solimp="0.998 0.998 0.001" solref="0.001 1" density="100" friction="0.95 0.3 0.1" type="box" pos="-0.00007 0.02401 0.00671" quat="0.60990 -0.35780 -0.35780 -0.60990" size="0.00051 0.00709 0.00848" group="0" rgba="0.8 0.8 0.8 0.3" />
      <geom solimp="0.998 0.998 0.001" solref="0.001 1" density="100" friction="0.95 0.3 0.1" type="box" pos="-0.01049 0.02155 0.00685" quat="0.45959 -0.42672 0.26704 0.73169" size="0.00051 0.00709 0.00848" group="0" rgba="0.8 0.8 0.8 0.3" />
      <geom solimp="0.998 0.998 0.001" solref="0.001 1" density="100" friction="0.95 0.3 0.1" type="box" pos="-0.01860 0.01506 0.00697" quat="0.29172 -0.47299 0.16619 0.81459" size="0.00051 0.00709 0.00848" group="0" rgba="0.8 0.8 0.8 0.3" />
      <geom solimp="0.998 0.998 0.001" solref="0.001 1" density="100" friction="0.95 0.3 0.1" type="box" pos="-0.02323 0.00567 0.00703" quat="0.10855 -0.49698 0.05658 0.85908" size="0.00051 0.00709 0.00848" group="0" rgba="0.8 0.8 0.8 0.3" />
      <geom solimp="0.998 0.998 0.001" solref="0.001 1" density="100" friction="0.95 0.3 0.1" type="box" pos="-0.02348 -0.00453 0.00703" quat="0.49761 -0.07722 0.86246 0.05074" size="0.00051 0.00709 0.00848" group="0" rgba="0.8 0.8 0.8 0.3" />
      <geom solimp="0.998 0.998 0.001" solref="0.001 1" density="100" friction="0.95 0.3 0.1" type="box" pos="-0.01923 -0.01422 0.00703" quat="0.47408 -0.26597 0.82406 0.15949" size="0.00051 0.00709 0.00848" group="0" rgba="0.8 0.8 0.8 0.3" />
      <geom solimp="0.998 0.998 0.001" solref="0.001 1" density="100" friction="0.95 0.3 0.1" type="box" pos="-0.01112 -0.02117 0.00703" quat="0.42646 -0.44336 0.74380 0.26138" size="0.00051 0.00709 0.00848" group="0" rgba="0.8 0.8 0.8 0.3" />
      <geom solimp="0.998 0.998 0.001" solref="0.001 1" density="100" friction="0.95 0.3 0.1" type="box" pos="-0.00087 -0.02390 0.00703" quat="0.59728 0.35787 0.34946 -0.62695" size="0.00051 0.00709 0.00848" group="0" rgba="0.8 0.8 0.8 0.3" />
      <geom solimp="0.998 0.998 0.001" solref="0.001 1" density="100" friction="0.95 0.3 0.1" type="box" pos="0.00965 -0.02188 0.00703" quat="0.72249 0.27055 0.42070 -0.47731" size="0.00051 0.00709 0.00848" group="0" rgba="0.8 0.8 0.8 0.3" />
      <geom solimp="0.998 0.998 0.001" solref="0.001 1" density="100" friction="0.95 0.3 0.1" type="box" pos="0.01802 -0.01572 0.00703" quat="0.17267 -0.80894 0.30891 0.46945" size="0.00051 0.00709 0.00848" group="0" rgba="0.8 0.8 0.8 0.3" />
      <geom solimp="0.998 0.998 0.001" solref="0.001 1" density="100" friction="0.95 0.3 0.1" type="box" pos="0.02302 -0.00650 0.00703" quat="0.85700 0.06550 0.49588 -0.12397" size="0.00051 0.00709 0.00848" group="0" rgba="0.8 0.8 0.8 0.3" />
      <geom solimp="0.998 0.998 0.001" solref="0.001 1" density="100" friction="0.95 0.3 0.1" type="box" pos="0.02302 -0.00650 0.00703" quat="0.85700 0.06550 0.49588 -0.12397" size="0.00051 0.00709 0.00848" group="0" rgba="0.8 0.8 0.8 0.3" />
      <geom solimp="0.998 0.998 0.001" solref="0.001 1" density="100" friction="0.95 0.3 0.1" type="box" pos="0.02391 0.00015 0.00703" quat="0.86591 -0.00473 0.50017 -0.00248" size="0.00051 0.00709 0.00848" group="0" rgba="0.8 0.8 0.8 0.3" />
      <geom solimp="0.998 0.998 0.001" solref="0.001 1" density="100" friction="0.95 0.3 0.1" type="box" pos="0.02169 0.01008 0.00703" quat="0.84663 -0.11101 0.48771 0.18175" size="0.00051 0.00709 0.00848" group="0" rgba="0.8 0.8 0.8 0.3" />
      <geom solimp="0.998 0.998 0.001" solref="0.001 1" density="100" friction="0.95 0.3 0.1" type="box" pos="0.01540 0.01830 0.00703" quat="0.21392 0.78724 0.36065 -0.45213" size="0.00051 0.00709 0.00848" group="0" rgba="0.8 0.8 0.8 0.3" />
      <geom solimp="0.998 0.998 0.001" solref="0.001 1" density="100" friction="0.95 0.3 0.1" type="box" pos="0.00826 0.02244 0.00703" quat="0.71324 -0.28870 0.40847 0.49101" size="0.00051 0.00709 0.00848" group="0" rgba="0.8 0.8 0.8 0.3" />
      <geom solimp="0.998 0.998 0.001" solref="0.001 1" density="100" friction="0.95 0.3 0.1" type="box" pos="-0.00007 0.03575 0.02264" quat="0.10134 0.69981 0.69981 -0.10134" size="0.00096 0.00709 0.01266" group="0" rgba="0.8 0.8 0.8 0.3" />
      <geom solimp="0.998 0.998 0.001" solref="0.001 1" density="100" friction="0.95 0.3 0.1" type="box" pos="-0.01308 0.03327 0.02264" quat="0.55811 -0.11836 0.08082 0.81730" size="0.00096 0.00709 0.01266" group="0" rgba="0.8 0.8 0.8 0.3" />
      <geom solimp="0.998 0.998 0.001" solref="0.001 1" density="100" friction="0.95 0.3 0.1" type="box" pos="-0.02408 0.02642 0.02264" quat="0.13104 0.40078 0.90490 -0.05804" size="0.00096 0.00709 0.01266" group="0" rgba="0.8 0.8 0.8 0.3" />
      <geom solimp="0.998 0.998 0.001" solref="0.001 1" density="100" friction="0.95 0.3 0.1" type="box" pos="-0.03197 0.01599 0.02264" quat="0.13945 0.22841 0.96296 -0.03308" size="0.00096 0.00709 0.01266" group="0" rgba="0.8 0.8 0.8 0.3" />
      <geom solimp="0.998 0.998 0.001" solref="0.001 1" density="100" friction="0.95 0.3 0.1" type="box" pos="-0.03558 0.00349 0.02264" quat="0.04942 -0.14314 0.00715 0.98844" size="0.00096 0.00709 0.01266" group="0" rgba="0.8 0.8 0.8 0.3" />
      <geom solimp="0.998 0.998 0.001" solref="0.001 1" density="100" friction="0.95 0.3 0.1" type="box" pos="-0.03456 -0.00914 0.02264" quat="0.14214 -0.12653 0.98155 0.01832" size="0.00096 0.00709 0.01266" group="0" rgba="0.8 0.8 0.8 0.3" />
      <geom solimp="0.998 0.998 0.001" solref="0.001 1" density="100" friction="0.95 0.3 0.1" type="box" pos="-0.02902 -0.02087 0.02264" quat="0.30259 0.13646 0.04382 -0.94228" size="0.00096 0.00709 0.01266" group="0" rgba="0.8 0.8 0.8 0.3" />
      <geom solimp="0.998 0.998 0.001" solref="0.001 1" density="100" friction="0.95 0.3 0.1" type="box" pos="-0.01954 -0.02993 0.02264" quat="0.12610 -0.47028 0.87081 0.06810" size="0.00096 0.00709 0.01266" group="0" rgba="0.8 0.8 0.8 0.3" />
      <geom solimp="0.998 0.998 0.001" solref="0.001 1" density="100" friction="0.95 0.3 0.1" type="box" pos="-0.00766 -0.03492 0.02264" quat="0.61947 0.11177 0.08971 -0.77183" size="0.00096 0.00709 0.01266" group="0" rgba="0.8 0.8 0.8 0.3" />
      <geom solimp="0.998 0.998 0.001" solref="0.001 1" density="100" friction="0.95 0.3 0.1" type="box" pos="0.00530 -0.03535 0.02264" quat="0.74921 0.09364 0.10849 -0.64664" size="0.00096 0.00709 0.01266" group="0" rgba="0.8 0.8 0.8 0.3" />
      <geom solimp="0.998 0.998 0.001" solref="0.001 1" density="100" friction="0.95 0.3 0.1" type="box" pos="0.01764 -0.03109 0.02264" quat="0.07226 -0.85468 0.49898 0.12377" size="0.00096 0.00709 0.01266" group="0" rgba="0.8 0.8 0.8 0.3" />
      <geom solimp="0.998 0.998 0.001" solref="0.001 1" density="100" friction="0.95 0.3 0.1" type="box" pos="0.02755 -0.02278 0.02264" quat="0.93084 0.04868 0.13480 -0.33615" size="0.00096 0.00709 0.01266" group="0" rgba="0.8 0.8 0.8 0.3" />
      <geom solimp="0.998 0.998 0.001" solref="0.001 1" density="100" friction="0.95 0.3 0.1" type="box" pos="0.03395 -0.01119 0.02264" quat="0.97700 0.02287 0.14148 -0.15791" size="0.00096 0.00709 0.01266" group="0" rgba="0.8 0.8 0.8 0.3" />
      <geom solimp="0.998 0.998 0.001" solref="0.001 1" density="100" friction="0.95 0.3 0.1" type="box" pos="0.03572 0.00140 0.02264" quat="0.00267 0.98951 0.01840 -0.14329" size="0.00096 0.00709 0.01266" group="0" rgba="0.8 0.8 0.8 0.3" />
      <geom solimp="0.998 0.998 0.001" solref="0.001 1" density="100" friction="0.95 0.3 0.1" type="box" pos="0.03572 0.00140 0.02264" quat="0.00267 0.98951 0.01840 -0.14329" size="0.00096 0.00709 0.01266" group="0" rgba="0.8 0.8 0.8 0.3" />
      <geom solimp="0.998 0.998 0.001" solref="0.001 1" density="100" friction="0.95 0.3 0.1" type="box" pos="0.03293 0.01390 0.02264" quat="0.02829 0.97021 0.19533 -0.14050" size="0.00096 0.00709 0.01266" group="0" rgba="0.8 0.8 0.8 0.3" />
      <geom solimp="0.998 0.998 0.001" solref="0.001 1" density="100" friction="0.95 0.3 0.1" type="box" pos="0.02592 0.02462 0.02264" quat="0.13315 0.36606 -0.91949 0.05301" size="0.00096 0.00709 0.01266" group="0" rgba="0.8 0.8 0.8 0.3" />
      <geom solimp="0.998 0.998 0.001" solref="0.001 1" density="100" friction="0.95 0.3 0.1" type="box" pos="0.01569 0.03212 0.02264" quat="0.83995 -0.07579 0.12163 0.52340" size="0.00096 0.00709 0.01266" group="0" rgba="0.8 0.8 0.8 0.3" />
      <geom solimp="0.998 0.998 0.001" solref="0.001 1" density="100" friction="0.95 0.3 0.1" type="box" pos="0.00801 0.03484 0.02264" quat="0.08915 0.77490 0.61562 -0.11222" size="0.00094 0.00337 0.01264" group="0" rgba="0.8 0.8 0.8 0.3" />
    </body>
    <body name="object_2_instance" pos="0.27445589652834834 -0.15642902036864503 0.44500000000000006">
      <freejoint />
      <geom solimp="0.998 0.998 0.001" solref="0.001 1" density="100" friction="0.95 0.3 0.1" type="mesh" mesh="object_2_model_vis" conaffinity="0" contype="0" group="1" material="object_2_model" />
      <geom solimp="0.998 0.998 0.001" solref="0.001 1" density="100" friction="0.95 0.3 0.1" type="box" pos="0.00000 0.00009 0.00240" quat="0.70711 0.00000 0.70711 0.00000" size="0.00184 0.01653 0.01728" group="0" rgba="0.8 0.8 0.8 0.3" />
      <geom solimp="0.998 0.998 0.001" solref="0.001 1" density="100" friction="0.95 0.3 0.1" type="box" pos="-0.00007 0.02401 0.00671" quat="0.60990 -0.35780 -0.35780 -0.60990" size="0.00051 0.00709 0.00848" group="0" rgba="0.8 0.8 0.8 0.3" />
      <geom solimp="0.998 0.998 0.001" solref="0.001 1" density="100" friction="0.95 0.3 0.1" type="box" pos="-0.01049 0.02155 0.00685" quat="0.45959 -0.42672 0.26704 0.73169" size="0.00051 0.00709 0.00848" group="0" rgba="0.8 0.8 0.8 0.3" />
      <geom solimp="0.998 0.998 0.001" solref="0.001 1" density="100" friction="0.95 0.3 0.1" type="box" pos="-0.01860 0.01506 0.00697" quat="0.29172 -0.47299 0.16619 0.81459" size="0.00051 0.00709 0.00848" group="0" rgba="0.8 0.8 0.8 0.3" />
      <geom solimp="0.998 0.998 0.001" solref="0.001 1" density="100" friction="0.95 0.3 0.1" type="box" pos="-0.02323 0.00567 0.00703" quat="0.10855 -0.49698 0.05658 0.85908" size="0.00051 0.00709 0.00848" group="0" rgba="0.8 0.8 0.8 0.3" />
      <geom solimp="0.998 0.998 0.001" solref="0.001 1" density="100" friction="0.95 0.3 0.1" type="box" pos="-0.02348 -0.00453 0.00703" quat="0.49761 -0.07722 0.86246 0.05074" size="0.00051 0.00709 0.00848" group="0" rgba="0.8 0.8 0.8 0.3" />
      <geom solimp="0.998 0.998 0.001" solref="0.001 1" density="100" friction="0.95 0.3 0.1" type="box" pos="-0.01923 -0.01422 0.00703" quat="0.47408 -0.26597 0.82406 0.15949" size="0.00051 0.00709 0.00848" group="0" rgba="0.8 0.8 0.8 0.3" />
      <geom solimp="0.998 0.998 0.001" solref="0.001 1" density="100" friction="0.95 0.3 0.1" type="box" pos="-0.01112 -0.02117 0.00703" quat="0.42646 -0.44336 0.74380 0.26138" size="0.00051 0.00709 0.00848" group="0" rgba="0.8 0.8 0.8 0.3" />
      <geom solimp="0.998 0.998 0.001" solref="0.001 1" density="100" friction="0.95 0.3 0.1" type="box" pos="-0.00087 -0.02390 0.00703" quat="0.59728 0.35787 0.34946 -0.62695" size="0.00051 0.00709 0.00848" group="0" rgba="0.8 0.8 0.8 0.3" />
      <geom solimp="0.998 0.998 0.001" solref="0.001 1" density="100" friction="0.95 0.3 0.1" type="box" pos="0.00965 -0.02188 0.00703" quat="0.72249 0.27055 0.42070 -0.47731" size="0.00051 0.00709 0.00848" group="0" rgba="0.8 0.8 0.8 0.3" />
      <geom solimp="0.998 0.998 0.001" solref="0.001 1" density="100" friction="0.95 0.3 0.1" type="box" pos="0.01802 -0.01572 0.00703" quat="0.17267 -0.80894 0.30891 0.46945" size="0.00051 0.00709 0.00848" group="0" rgba="0.8 0.8 0.8 0.3" />
      <geom solimp="0.998 0.998 0.001" solref="0.001 1" density="100" friction="0.95 0.3 0.1" type="box" pos="0.02302 -0.00650 0.00703" quat="0.85700 0.06550 0.49588 -0.12397" size="0.00051 0.00709 0.00848" group="0" rgba="0.8 0.8 0.8 0.3" />
      <geom solimp="0.998 0.998 0.001" solref="0.001 1" density="100" friction="0.95 0.3 0.1" type="box" pos="0.02302 -0.00650 0.00703" quat="0.85700 0.06550 0.49588 -0.12397" size="0.00051 0.00709 0.00848" group="0" rgba="0.8 0.8 0.8 0.3" />
      <geom solimp="0.998 0.998 0.001" solref="0.001 1" density="100" friction="0.95 0.3 0.1" type="box" pos="0.02391 0.00015 0.00703" quat="0.86591 -0.00473 0.50017 -0.00248" size="0.00051 0.00709 0.00848" group="0" rgba="0.8 0.8 0.8 0.3" />
      <geom solimp="0.998 0.998 0.001" solref="0.001 1" density="100" friction="0.95 0.3 0.1" type="box" pos="0.02169 0.01008 0.00703" quat="0.84663 -0.11101 0.48771 0.18175" size="0.00051 0.00709 0.00848" group="0" rgba="0.8 0.8 0.8 0.3" />
      <geom solimp="0.998 0.998 0.001" solref="0.001 1" density="100" friction="0.95 0.3 0.1" type="box" pos="0.01540 0.01830 0.00703" quat="0.21392 0.78724 0.36065 -0.45213" size="0.00051 0.00709 0.00848" group="0" rgba="0.8 0.8 0.8 0.3" />
      <geom solimp="0.998 0.998 0.001" solref="0.001 1" density="100" friction="0.95 0.3 0.1" type="box" pos="0.00826 0.02244 0.00703" quat="0.71324 -0.28870 0.40847 0.49101" size="0.00051 0.00709 0.00848" group="0" rgba="0.8 0.8 0.8 0.3" />
      <geom solimp="0.998 0.998 0.001" solref="0.001 1" density="100" friction="0.95 0.3 0.1" type="box" pos="-0.00007 0.03575 0.02264" quat="0.10134 0.69981 0.69981 -0.10134" size="0.00096 0.00709 0.01266" group="0" rgba="0.8 0.8 0.8 0.3" />
      <geom solimp="0.998 0.998 0.001" solref="0.001 1" density="100" friction="0.95 0.3 0.1" type="box" pos="-0.01308 0.03327 0.02264" quat="0.55811 -0.11836 0.08082 0.81730" size="0.00096 0.00709 0.01266" group="0" rgba="0.8 0.8 0.8 0.3" />
      <geom solimp="0.998 0.998 0.001" solref="0.001 1" density="100" friction="0.95 0.3 0.1" type="box" pos="-0.02408 0.02642 0.02264" quat="0.13104 0.40078 0.90490 -0.05804" size="0.00096 0.00709 0.01266" group="0" rgba="0.8 0.8 0.8 0.3" />
      <geom solimp="0.998 0.998 0.001" solref="0.001 1" density="100" friction="0.95 0.3 0.1" type="box" pos="-0.03197 0.01599 0.02264" quat="0.13945 0.22841 0.96296 -0.03308" size="0.00096 0.00709 0.01266" group="0" rgba="0.8 0.8 0.8 0.3" />
      <geom solimp="0.998 0.998 0.001" solref="0.001 1" density="100" friction="0.95 0.3 0.1" type="box" pos="-0.03558 0.00349 0.02264" quat="0.04942 -0.14314 0.00715 0.98844" size="0.00096 0.00709 0.01266" group="0" rgba="0.8 0.8 0.8 0.3" />
      <geom solimp="0.998 0.998 0.001" solref="0.001 1" density="100" friction="0.95 0.3 0.1" type="box" pos="-0.03456 -0.00914 0.02264" quat="0.14214 -0.12653 0.98155 0.01832" size="0.00096 0.00709 0.01266" group="0" rgba="0.8 0.8 0.8 0.3" />
      <geom solimp="0.998 0.998 0.001" solref="0.001 1" density="100" friction="0.95 0.3 0.1" type="box" pos="-0.02902 -0.02087 0.02264" quat="0.30259 0.13646 0.04382 -0.94228" size="0.00096 0.00709 0.01266" group="0" rgba="0.8 0.8 0.8 0.3" />
      <geom solimp="0.998 0.998 0.001" solref="0.001 1" density="100" friction="0.95 0.3 0.1" type="box" pos="-0.01954 -0.02993 0.02264" quat="0.12610 -0.47028 0.87081 0.06810" size="0.00096 0.00709 0.01266" group="0" rgba="0.8 0.8 0.8 0.3" />
      <geom solimp="0.998 0.998 0.001" solref="0.001 1" density="100" friction="0.95 0.3 0.1" type="box" pos="-0.00766 -0.03492 0.02264" quat="0.61947 0.11177 0.08971 -0.77183" size="0.00096 0.00709 0.01266" group="0" rgba="0.8 0.8 0.8 0.3" />
      <geom solimp="0.998 0.998 0.001" solref="0.001 1" density="100" friction="0.95 0.3 0.1" type="box" pos="0.00530 -0.03535 0.02264" quat="0.74921 0.09364 0.10849 -0.64664" size="0.00096 0.00709 0.01266" group="0" rgba="0.8 0.8 0.8 0.3" />
      <geom solimp="0.998 0.998 0.001" solref="0.001 1" density="100" friction="0.95 0.3 0.1" type="box" pos="0.01764 -0.03109 0.02264" quat="0.07226 -0.85468 0.49898 0.12377" size="0.00096 0.00709 0.01266" group="0" rgba="0.8 0.8 0.8 0.3" />
      <geom solimp="0.998 0.998 0.001" solref="0.001 1" density="100" friction="0.95 0.3 0.1" type="box" pos="0.02755 -0.02278 0.02264" quat="0.93084 0.04868 0.13480 -0.33615" size="0.00096 0.00709 0.01266" group="0" rgba="0.8 0.8 0.8 0.3" />
      <geom solimp="0.998 0.998 0.001" solref="0.001 1" density="100" friction="0.95 0.3 0.1" type="box" pos="0.03395 -0.01119 0.02264" quat="0.97700 0.02287 0.14148 -0.15791" size="0.00096 0.00709 0.01266" group="0" rgba="0.8 0.8 0.8 0.3" />
      <geom solimp="0.998 0.998 0.001" solref="0.001 1" density="100" friction="0.95 0.3 0.1" type="box" pos="0.03572 0.00140 0.02264" quat="0.00267 0.98951 0.01840 -0.14329" size="0.00096 0.00709 0.01266" group="0" rgba="0.8 0.8 0.8 0.3" />
      <geom solimp="0.998 0.998 0.001" solref="0.001 1" density="100" friction="0.95 0.3 0.1" type="box" pos="0.03572 0.00140 0.02264" quat="0.00267 0.98951 0.01840 -0.14329" size="0.00096 0.00709 0.01266" group="0" rgba="0.8 0.8 0.8 0.3" />
      <geom solimp="0.998 0.998 0.001" solref="0.001 1" density="100" friction="0.95 0.3 0.1" type="box" pos="0.03293 0.01390 0.02264" quat="0.02829 0.97021 0.19533 -0.14050" size="0.00096 0.00709 0.01266" group="0" rgba="0.8 0.8 0.8 0.3" />
      <geom solimp="0.998 0.998 0.001" solref="0.001 1" density="100" friction="0.95 0.3 0.1" type="box" pos="0.02592 0.02462 0.02264" quat="0.13315 0.36606 -0.91949 0.05301" size="0.00096 0.00709 0.01266" group="0" rgba="0.8 0.8 0.8 0.3" />
      <geom solimp="0.998 0.998 0.001" solref="0.001 1" density="100" friction="0.95 0.3 0.1" type="box" pos="0.01569 0.03212 0.02264" quat="0.83995 -0.07579 0.12163 0.52340" size="0.00096 0.00709 0.01266" group="0" rgba="0.8 0.8 0.8 0.3" />
      <geom solimp="0.998 0.998 0.001" solref="0.001 1" density="100" friction="0.95 0.3 0.1" type="box" pos="0.00801 0.03484 0.02264" quat="0.08915 0.77490 0.61562 -0.11222" size="0.00094 0.00337 0.01264" group="0" rgba="0.8 0.8 0.8 0.3" />
    </body>
    <body name="object_3_instance" pos="0.49247769598956026 0.020816559850205654 0.44500000000000006">
      <freejoint />
      <geom solimp="0.998 0.998 0.001" solref="0.001 1" density="100" friction="0.95 0.3 0.1" type="mesh" mesh="object_3_textured_vis" conaffinity="0" contype="0" group="1" material="object_3_textured" />
      <geom solimp="0.998 0.998 0.001" solref="0.001 1" density="100" friction="0.95 0.3 0.1" type="box" pos="0.00045 -0.03935 0.00079" quat="0.50000 0.50000 0.50000 -0.50000" size="0.01695 0.02811 0.03307" group="0" rgba="0.8 0.8 0.8 0.3" />
      <geom solimp="0.998 0.998 0.001" solref="0.001 1" density="100" friction="0.95 0.3 0.1" type="box" pos="0.00045 0.00369 0.00079" quat="0.50000 0.50000 -0.50000 -0.50000" size="0.01126 0.01834 0.02393" group="0" rgba="0.8 0.8 0.8 0.3" />
      <geom solimp="0.998 0.998 0.001" solref="0.001 1" density="100" friction="0.95 0.3 0.1" type="box" pos="0.00045 0.02513 0.00079" quat="0.50000 0.50000 -0.50000 -0.50000" size="0.01126 0.01834 0.01869" group="0" rgba="0.8 0.8 0.8 0.3" />
      <geom solimp="0.998 0.998 0.001" solref="0.001 1" density="100" friction="0.95 0.3 0.1" type="box" pos="0.00045 0.05471 0.00079" quat="0.00000 -0.00000 0.70711 -0.70711" size="0.01032 0.01414 0.01848" group="0" rgba="0.8 0.8 0.8 0.3" />
      <geom solimp="0.998 0.998 0.001" solref="0.001 1" density="100" friction="0.95 0.3 0.1" type="box" pos="0.01368 0.05471 0.00079" quat="0.70711 0.70711 0.00000 -0.00000" size="0.00292 0.00405 0.01848" group="0" rgba="0.8 0.8 0.8 0.3" />
      <geom solimp="0.998 0.998 0.001" solref="0.001 1" density="100" friction="0.95 0.3 0.1" type="box" pos="-0.01322 0.05471 0.00079" quat="0.00000 0.00000 0.70711 0.70711" size="0.00315 0.00460 0.01848" group="0" rgba="0.8 0.8 0.8 0.3" />
      <geom solimp="0.998 0.998 0.001" solref="0.001 1" density="100" friction="0.95 0.3 0.1" type="box" pos="0.00008 0.05471 -0.01554" quat="0.50000 -0.50000 0.50000 0.50000" size="0.00209 0.00685 0.01848" group="0" rgba="0.8 0.8 0.8 0.3" />
      <geom solimp="0.998 0.998 0.001" solref="0.001 1" density="100" friction="0.95 0.3 0.1" type="box" pos="0.00002 0.05471 0.01682" quat="0.50000 -0.50000 0.50000 0.50000" size="0.00186 0.00740 0.01848" group="0" rgba="0.8 0.8 0.8 0.3" />
      <geom solimp="0.998 0.998 0.001" solref="0.001 1" density="100" friction="0.95 0.3 0.1" type="box" pos="0.01333 0.05471 0.00901" quat="0.70711 0.70711 0.00000 -0.00000" size="0.00259 0.00413 0.01848" group="0" rgba="0.8 0.8 0.8 0.3" />
      <geom solimp="0.998 0.998 0.001" solref="0.001 1" density="100" friction="0.95 0.3 0.1" type="box" pos="0.01333 0.05471 -0.00727" quat="0.00000 0.00000 0.70711 0.70711" size="0.00259 0.00392 0.01848" group="0" rgba="0.8 0.8 0.8 0.3" />
      <geom solimp="0.998 0.998 0.001" solref="0.001 1" density="100" friction="0.95 0.3 0.1" type="box" pos="-0.01254 0.05471 -0.00799" quat="0.00000 0.00000 0.70711 0.70711" size="0.00259 0.00405 0.01848" group="0" rgba="0.8 0.8 0.8 0.3" />
      <geom solimp="0.998 0.998 0.001" solref="0.001 1" density="100" friction="0.95 0.3 0.1" type="box" pos="-0.01259 0.05471 0.00929" quat="0.00000 0.00000 0.70711 0.70711" size="0.00259 0.00380 0.01848" group="0" rgba="0.8 0.8 0.8 0.3" />
    </body>
    <body name="object_4_instance" pos="0.48158555389930063 0.07942052278306176 0.44500000000000006">
      <freejoint />
      <geom solimp="0.998 0.998 0.001" solref="0.001 1" density="100" friction="0.95 0.3 0.1" type="mesh" mesh="object_4_textured_vis" conaffinity="0" contype="0" group="1" material="object_4_textured" />
      <geom solimp="0.998 0.998 0.001" solref="0.001 1" density="100" friction="0.95 0.3 0.1" type="box" pos="0.00045 -0.03935 0.00079" quat="0.50000 0.50000 0.50000 -0.50000" size="0.01695 0.02811 0.03307" group="0" rgba="0.8 0.8 0.8 0.3" />
      <geom solimp="0.998 0.998 0.001" solref="0.001 1" density="100" friction="0.95 0.3 0.1" type="box" pos="0.00045 0.00369 0.00079" quat="0.50000 0.50000 -0.50000 -0.50000" size="0.01126 0.01834 0.02393" group="0" rgba="0.8 0.8 0.8 0.3" />
      <geom solimp="0.998 0.998 0.001" solref="0.001 1" density="100" friction="0.95 0.3 0.1" type="box" pos="0.00045 0.02513 0.00079" quat="0.50000 0.50000 -0.50000 -0.50000" size="0.01126 0.01834 0.01869" group="0" rgba="0.8 0.8 0.8 0.3" />
      <geom solimp="0.998 0.998 0.001" solref="0.001 1" density="100" friction="0.95 0.3 0.1" type="box" pos="0.00045 0.05471 0.00079" quat="0.00000 -0.00000 0.70711 -0.70711" size="0.01032 0.01414 0.01848" group="0" rgba="0.8 0.8 0.8 0.3" />
      <geom solimp="0.998 0.998 0.001" solref="0.001 1" density="100" friction="0.95 0.3 0.1" type="box" pos="0.01368 0.05471 0.00079" quat="0.70711 0.70711 0.00000 -0.00000" size="0.00292 0.00405 0.01848" group="0" rgba="0.8 0.8 0.8 0.3" />
      <geom solimp="0.998 0.998 0.001" solref="0.001 1" density="100" friction="0.95 0.3 0.1" type="box" pos="-0.01322 0.05471 0.00079" quat="0.00000 0.00000 0.70711 0.70711" size="0.00315 0.00460 0.01848" group="0" rgba="0.8 0.8 0.8 0.3" />
      <geom solimp="0.998 0.998 0.001" solref="0.001 1" density="100" friction="0.95 0.3 0.1" type="box" pos="0.00008 0.05471 -0.01554" quat="0.50000 -0.50000 0.50000 0.50000" size="0.00209 0.00685 0.01848" group="0" rgba="0.8 0.8 0.8 0.3" />
      <geom solimp="0.998 0.998 0.001" solref="0.001 1" density="100" friction="0.95 0.3 0.1" type="box" pos="0.00002 0.05471 0.01682" quat="0.50000 -0.50000 0.50000 0.50000" size="0.00186 0.00740 0.01848" group="0" rgba="0.8 0.8 0.8 0.3" />
      <geom solimp="0.998 0.998 0.001" solref="0.001 1" density="100" friction="0.95 0.3 0.1" type="box" pos="0.01333 0.05471 0.00901" quat="0.70711 0.70711 0.00000 -0.00000" size="0.00259 0.00413 0.01848" group="0" rgba="0.8 0.8 0.8 0.3" />
      <geom solimp="0.998 0.998 0.001" solref="0.001 1" density="100" friction="0.95 0.3 0.1" type="box" pos="0.01333 0.05471 -0.00727" quat="0.00000 0.00000 0.70711 0.70711" size="0.00259 0.00392 0.01848" group="0" rgba="0.8 0.8 0.8 0.3" />
      <geom solimp="0.998 0.998 0.001" solref="0.001 1" density="100" friction="0.95 0.3 0.1" type="box" pos="-0.01254 0.05471 -0.00799" quat="0.00000 0.00000 0.70711 0.70711" size="0.00259 0.00405 0.01848" group="0" rgba="0.8 0.8 0.8 0.3" />
      <geom solimp="0.998 0.998 0.001" solref="0.001 1" density="100" friction="0.95 0.3 0.1" type="box" pos="-0.01259 0.05471 0.00929" quat="0.00000 0.00000 0.70711 0.70711" size="0.00259 0.00380 0.01848" group="0" rgba="0.8 0.8 0.8 0.3" />
    </body>
    <body name="base_link" pos="-1.6 0.0 0.0">
      <inertial pos="0 0 0.035" mass="60" diaginertia="0.001 0.001 0.001" />
      <joint name="joint_x" type="slide" axis="1 0 0" />
      <joint name="joint_y" type="slide" axis="0 1 0" />
      <joint name="joint_th" />
      <geom class="base/visual" mesh="tidybot_bumper" material="tidybot_black" />
      <geom class="base/visual" mesh="tidybot_bottom_plate" material="tidybot_dark_gray" />
      <geom class="base/visual" mesh="tidybot_body" material="tidybot_gray" />
      <geom class="base/visual" mesh="tidybot_top_plate" material="tidybot_dark_gray" />
      <geom class="base/visual" mesh="tidybot_arm_plate" material="tidybot_gray" />
      <geom class="base/collision" mesh="tidybot_bumper" />
      <geom class="base/collision" mesh="tidybot_bottom_plate" />
      <geom class="base/collision" mesh="tidybot_body" />
      <geom class="base/collision" mesh="tidybot_top_plate" />
      <geom class="base/collision" mesh="tidybot_arm_plate" />
      <camera name="base" pos="0.2525 0 0.335" euler="0 -0.7853981634 -1.5707963268" fovy="52.23384539951277" resolution="640 360" />
      <body name="gen3/base_link" pos="0 0 0.335" quat="1 0 0 0">
        <inertial pos="-0.000648 -0.000166 0.084487" quat="0.999294 0.00139618 -0.0118387 0.035636" mass="1.697" diaginertia="0.00462407 0.00449437 0.00207755" />
        <geom class="gen3/visual" mesh="tidybot_gen3/base_link" />
        <geom class="gen3/collision" mesh="tidybot_gen3/base_link" />
        <body name="shoulder_link" pos="0 0 0.15643" quat="0 1 0 0">
          <inertial pos="-2.3e-05 -0.010364 -0.07336" quat="0.707051 0.0451246 -0.0453544 0.704263" mass="1.3773" diaginertia="0.00488868 0.00457 0.00135132" />
          <joint name="joint_1" />
          <geom class="gen3/visual" mesh="tidybot_shoulder_link" />
          <geom class="gen3/collision" mesh="tidybot_shoulder_link" />
          <body name="half_arm_1_link" pos="0 0.005375 -0.12838" quat="1 1 0 0">
            <inertial pos="-4.4e-05 -0.09958 -0.013278" quat="0.482348 0.516286 -0.516862 0.483366" mass="1.1636" diaginertia="0.0113017 0.011088 0.00102532" />
            <joint name="joint_2" range="-2.24 2.24" />
            <geom class="gen3/visual" mesh="tidybot_half_arm_1_link" />
            <geom class="gen3/collision" mesh="tidybot_half_arm_1_link" />
            <body name="half_arm_2_link" pos="0 -0.21038 -0.006375" quat="1 -1 0 0">
              <inertial pos="-4.4e-05 -0.006641 -0.117892" quat="0.706144 0.0213722 -0.0209128 0.707437" mass="1.1636" diaginertia="0.0111633 0.010932 0.00100671" />
              <joint name="joint_3" />
              <geom class="gen3/visual" mesh="tidybot_half_arm_2_link" />
              <geom class="gen3/collision" mesh="tidybot_half_arm_2_link" />
              <body name="forearm_link" pos="0 0.006375 -0.21038" quat="1 1 0 0">
                <inertial pos="-1.8e-05 -0.075478 -0.015006" quat="0.483678 0.515961 -0.515859 0.483455" mass="0.9302" diaginertia="0.00834839 0.008147 0.000598606" />
                <joint name="joint_4" range="-2.57 2.57" />
                <geom class="gen3/visual" mesh="tidybot_forearm_link" />
                <geom class="gen3/collision" mesh="tidybot_forearm_link" />
                <body name="spherical_wrist_1_link" pos="0 -0.20843 -0.006375" quat="1 -1 0 0">
                  <inertial pos="1e-06 -0.009432 -0.063883" quat="0.703558 0.0707492 -0.0707492 0.703558" mass="0.6781" diaginertia="0.00165901 0.001596 0.000346988" />
                  <joint name="joint_5" />
                  <geom class="gen3/visual" mesh="tidybot_spherical_wrist_1_link" />
                  <geom class="gen3/collision" mesh="tidybot_spherical_wrist_1_link" />
                  <body name="spherical_wrist_2_link" pos="0 0.00017505 -0.10593" quat="1 1 0 0">
                    <inertial pos="1e-06 -0.045483 -0.00965" quat="0.44426 0.550121 -0.550121 0.44426" mass="0.6781" diaginertia="0.00170087 0.001641 0.00035013" />
                    <joint name="joint_6" range="-2.09 2.09" />
                    <geom class="gen3/visual" mesh="tidybot_spherical_wrist_2_link" />
                    <geom class="gen3/collision" mesh="tidybot_spherical_wrist_2_link" />
                    <body name="bracelet_link" pos="0 -0.10593 -0.00017505" quat="1 -1 0 0">
                      <inertial pos="0.000281 0.011402 -0.029798" quat="0.394358 0.596779 -0.577293 0.393789" mass="0.5" diaginertia="0.000657336 0.000587019 0.000320645" />
                      <joint name="joint_7" />
                      <geom class="gen3/visual" mesh="tidybot_bracelet_with_vision_link" />
                      <geom class="gen3/collision" mesh="tidybot_bracelet_with_vision_link" />
                      <body name="base" pos="0 0 -0.06149039" quat="0 -1 1 0" childclass="2f85">
                        <inertial mass="0.777441" pos="0 -2.70394e-05 0.0354675" quat="1 -0.00152849 0 0" diaginertia="0.000260285 0.000225381 0.000152708" />
                        <geom class="2f85/visual" mesh="tidybot_base" material="tidybot_2f85/black" />
                        <geom class="2f85/collision" mesh="tidybot_base" />
                        <body name="right_driver" pos="0 0.0306011 0.054904">
                          <inertial mass="0.00899563" pos="2.96931e-12 0.0177547 0.00107314" quat="0.681301 0.732003 0 0" diaginertia="1.72352e-06 1.60906e-06 3.22006e-07" />
                          <joint name="right_driver_joint" class="driver" />
                          <geom class="2f85/visual" mesh="tidybot_driver" material="tidybot_2f85/gray" />
                          <geom class="2f85/collision" mesh="tidybot_driver" />
                          <body name="right_coupler" pos="0 0.0315 -0.0041">
                            <inertial mass="0.0140974" pos="0 0.00301209 0.0232175" quat="0.705636 -0.0455904 0.0455904 0.705636" diaginertia="4.16206e-06 3.52216e-06 8.88131e-07" />
                            <joint name="right_coupler_joint" class="coupler" />
                            <geom class="2f85/visual" mesh="tidybot_coupler" material="tidybot_2f85/black" />
                            <geom class="2f85/collision" mesh="tidybot_coupler" />
                          </body>
                        </body>
                        <body name="right_spring_link" pos="0 0.0132 0.0609">
                          <inertial mass="0.0221642" pos="-8.65005e-09 0.0181624 0.0212658" quat="0.663403 -0.244737 0.244737 0.663403" diaginertia="8.96853e-06 6.71733e-06 2.63931e-06" />
                          <joint name="right_spring_link_joint" class="spring_link" />
                          <geom class="2f85/visual" mesh="tidybot_spring_link" material="tidybot_2f85/black" />
                          <geom class="2f85/collision" mesh="tidybot_spring_link" />
                          <body name="right_follower" pos="0 0.055 0.0375">
                            <inertial mass="0.0125222" pos="0 -0.011046 0.0124786" quat="1 0.1664 0 0" diaginertia="2.67415e-06 2.4559e-06 6.02031e-07" />
                            <joint name="right_follower_joint" class="follower" />
                            <geom class="2f85/visual" mesh="tidybot_follower" material="tidybot_2f85/black" />
                            <geom class="2f85/collision" mesh="tidybot_follower" />
                            <body name="right_pad" pos="0 -0.0189 0.01352">
                              <geom class="pad_box1" name="right_pad1" />
                              <geom class="pad_box2" name="right_pad2" />
                              <inertial mass="0.0035" pos="0 -0.0025 0.0185" quat="0.707107 0 0 0.707107" diaginertia="4.73958e-07 3.64583e-07 1.23958e-07" />
                              <geom class="2f85/visual" mesh="tidybot_pad" />
                              <body name="right_silicone_pad">
                                <geom class="2f85/visual" mesh="tidybot_silicone_pad" material="tidybot_2f85/black" />
                              </body>
                            </body>
                          </body>
                        </body>
                        <body name="left_driver" pos="0 -0.0306011 0.054904" quat="0 0 0 1">
                          <inertial mass="0.00899563" pos="0 0.0177547 0.00107314" quat="0.681301 0.732003 0 0" diaginertia="1.72352e-06 1.60906e-06 3.22006e-07" />
                          <joint name="left_driver_joint" class="driver" />
                          <geom class="2f85/visual" mesh="tidybot_driver" material="tidybot_2f85/gray" />
                          <geom class="2f85/collision" mesh="tidybot_driver" />
                          <body name="left_coupler" pos="0 0.0315 -0.0041">
                            <inertial mass="0.0140974" pos="0 0.00301209 0.0232175" quat="0.705636 -0.0455904 0.0455904 0.705636" diaginertia="4.16206e-06 3.52216e-06 8.88131e-07" />
                            <joint name="left_coupler_joint" class="coupler" />
                            <geom class="2f85/visual" mesh="tidybot_coupler" material="tidybot_2f85/black" />
                            <geom class="2f85/collision" mesh="tidybot_coupler" />
                          </body>
                        </body>
                        <body name="left_spring_link" pos="0 -0.0132 0.0609" quat="0 0 0 1">
                          <inertial mass="0.0221642" pos="-8.65005e-09 0.0181624 0.0212658" quat="0.663403 -0.244737 0.244737 0.663403" diaginertia="8.96853e-06 6.71733e-06 2.63931e-06" />
                          <joint name="left_spring_link_joint" class="spring_link" />
                          <geom class="2f85/visual" mesh="tidybot_spring_link" material="tidybot_2f85/black" />
                          <geom class="2f85/collision" mesh="tidybot_spring_link" />
                          <body name="left_follower" pos="0 0.055 0.0375">
                            <inertial mass="0.0125222" pos="0 -0.011046 0.0124786" quat="1 0.1664 0 0" diaginertia="2.67415e-06 2.4559e-06 6.02031e-07" />
                            <joint name="left_follower_joint" class="follower" />
                            <geom class="2f85/visual" mesh="tidybot_follower" material="tidybot_2f85/black" />
                            <geom class="2f85/collision" mesh="tidybot_follower" />
                            <body name="left_pad" pos="0 -0.0189 0.01352">
                              <geom class="pad_box1" name="left_pad1" />
                              <geom class="pad_box2" name="left_pad2" />
                              <inertial mass="0.0035" pos="0 -0.0025 0.0185" quat="1 0 0 1" diaginertia="4.73958e-07 3.64583e-07 1.23958e-07" />
                              <geom class="2f85/visual" mesh="tidybot_pad" />
                              <body name="left_silicone_pad">
                                <geom class="2f85/visual" mesh="tidybot_silicone_pad" material="tidybot_2f85/black" />
                              </body>
                            </body>
                          </body>
                        </body>
                      </body>
                      <camera name="wrist" pos="0 -0.05639 -0.058475" quat="0 0 0 1" fovy="41.83792730009236" resolution="640 480" />
                      <site name="pinch_site" pos="0 0 -0.181525" quat="0 1 0 0" />
                    </body>
                  </body>
                </body>
              </body>
            </body>
          </body>
        </body>
      </body>
    </body>
  </worldbody>
  <default>
    <default class="base">
      <default class="base/visual">
        <geom type="mesh" contype="0" conaffinity="0" group="2" />
      </default>
      <default class="base/collision">
        <geom type="mesh" group="3" />
      </default>
    </default>
    <default class="gen3">
      <default class="gen3/visual">
        <geom type="mesh" contype="0" conaffinity="0" group="2" rgba="0.75294 0.75294 0.75294 1" />
      </default>
      <default class="gen3/collision">
        <geom type="mesh" group="3" />
      </default>
      <default class="large_actuator">
        <position kp="2000" kv="100" forcerange="-105 105" />
      </default>
      <default class="small_actuator">
        <position kp="500" kv="50" forcerange="-52 52" />
      </default>
    </default>
    <default class="2f85">
      <mesh scale="0.001 0.001 0.001" />
      <general biastype="affine" />
      <joint axis="1 0 0" />
      <default class="driver">
        <joint range="0 0.8" armature="0.005" damping="0.1" solimplimit="0.95 0.99 0.001" solreflimit="0.005 1" />
      </default>
      <default class="follower">
        <joint range="-0.872664 0.872664" armature="0.001" pos="0 -0.018 0.0065" solimplimit="0.95 0.99 0.001" solreflimit="0.005 1" />
      </default>
      <default class="spring_link">
        <joint range="-0.29670597283 0.8" armature="0.001" stiffness="0.05" springref="2.62" damping="0.00125" />
      </default>
      <default class="coupler">
        <joint range="-1.57 0" armature="0.001" solimplimit="0.95 0.99 0.001" solreflimit="0.005 1" />
      </default>
      <default class="2f85/visual">
        <geom type="mesh" contype="0" conaffinity="0" group="2" />
      </default>
      <default class="2f85/collision">
        <geom type="mesh" group="3" />
        <default class="pad_box1">
          <geom mass="0" type="box" pos="0 -0.0026 0.028125" size="0.011 0.004 0.009375" friction="0.7" solimp="0.95 0.99 0.001" solref="0.004 1" priority="1" rgba="0.55 0.55 0.55 1" />
        </default>
        <default class="pad_box2">
          <geom mass="0" type="box" pos="0 -0.0026 0.009375" size="0.011 0.004 0.009375" friction="0.6" solimp="0.95 0.99 0.001" solref="0.004 1" priority="1" rgba="0.45 0.45 0.45 1" />
        </default>
      </default>
    </default>
    <site size="0.001" rgba="0.5 0.5 0.5 0.3" group="4" />
  </default>
  <contact>
    <exclude body1="base" body2="left_driver" />
    <exclude body1="base" body2="right_driver" />
    <exclude body1="base" body2="left_spring_link" />
    <exclude body1="base" body2="right_spring_link" />
    <exclude body1="right_coupler" body2="right_follower" />
    <exclude body1="left_coupler" body2="left_follower" />
  </contact>
  <tendon>
    <fixed name="split">
      <joint joint="right_driver_joint" coef="0.5" />
      <joint joint="left_driver_joint" coef="0.5" />
    </fixed>
  </tendon>
  <equality>
    <connect anchor="0 0 0" body1="right_follower" body2="right_coupler" solimp="0.95 0.99 0.001" solref="0.005 1" />
    <connect anchor="0 0 0" body1="left_follower" body2="left_coupler" solimp="0.95 0.99 0.001" solref="0.005 1" />
    <joint joint1="right_driver_joint" joint2="left_driver_joint" polycoef="0 1 0 0 0" solimp="0.95 0.99 0.001" solref="0.005 1" />
  </equality>
  <actuator>
    <position name="joint_x" joint="joint_x" kp="1000000" kv="50000" />
    <position name="joint_y" joint="joint_y" kp="1000000" kv="50000" />
    <position name="joint_th" joint="joint_th" kp="50000" kv="1000" />
    <position class="large_actuator" name="joint_1" joint="joint_1" />
    <position class="large_actuator" name="joint_2" joint="joint_2" ctrlrange="-2.2497294058206907 2.2497294058206907" />
    <position class="large_actuator" name="joint_3" joint="joint_3" />
    <position class="large_actuator" name="joint_4" joint="joint_4" ctrlrange="-2.5795966344476193 2.5795966344476193" />
    <position class="small_actuator" name="joint_5" joint="joint_5" />
    <position class="small_actuator" name="joint_6" joint="joint_6" ctrlrange="-2.0996310901491784 2.0996310901491784" />
    <position class="small_actuator" name="joint_7" joint="joint_7" />
    <general class="2f85" name="fingers_actuator" tendon="split" forcerange="-5 5" ctrlrange="0 255" gainprm="0.3137255 0 0" biasprm="0 -100 -10" />
  </actuator>
</mujoco>